<?xml version="1.0" encoding="UTF-8"?>
<!-- Generated by org.testng.reporters.JUnitReportReporter -->
<testsuite skipped="0" hostname="DESKTOP-9E5ICTO" name="practice.InvocationTestCount" tests="10" failures="0" timestamp="22 Nov 2019 22:34:03 GMT" time="0.068" errors="1">
  <testcase name="test1" time="0.006" classname="practice.InvocationTestCount"/>
  <testcase name="test1" time="0.008" classname="practice.InvocationTestCount"/>
  <testcase name="test1" time="0.004" classname="practice.InvocationTestCount"/>
  <testcase name="test1" time="0.004" classname="practice.InvocationTestCount"/>
  <testcase name="test1" time="0.018" classname="practice.InvocationTestCount"/>
  <testcase name="test1" time="0.004" classname="practice.InvocationTestCount"/>
  <testcase name="test1" time="0.004" classname="practice.InvocationTestCount"/>
  <testcase name="test1" time="0.007" classname="practice.InvocationTestCount">
    <error type="org.testng.TestException" message="
Expected exception of type class java.lang.ArithmeticException but got org.testng.internal.thread.ThreadTimeoutException: Method practice.InvocationTestCount.test1() didn&#039;t finish within the time-out 2">
      <![CDATA[org.testng.TestException: 
Expected exception of type class java.lang.ArithmeticException but got org.testng.internal.thread.ThreadTimeoutException: Method practice.InvocationTestCount.test1() didn't finish within the time-out 2
at org.testng.internal.ExpectedExceptionsHolder.wrongException(ExpectedExceptionsHolder.java:68)
at org.testng.internal.Invoker.considerExceptions(Invoker.java:1130)
at org.testng.internal.Invoker.invokeMethod(Invoker.java:615)
at org.testng.internal.Invoker.invokeTestMethod(Invoker.java:719)
at org.testng.internal.Invoker.invokeTestMethods(Invoker.java:989)
at org.testng.internal.TestMethodWorker.invokeTestMethods(TestMethodWorker.java:125)
at org.testng.internal.TestMethodWorker.run(TestMethodWorker.java:109)
at org.testng.TestRunner.privateRun(TestRunner.java:648)
at org.testng.TestRunner.run(TestRunner.java:505)
at org.testng.SuiteRunner.runTest(SuiteRunner.java:455)
at org.testng.SuiteRunner.runSequentially(SuiteRunner.java:450)
at org.testng.SuiteRunner.privateRun(SuiteRunner.java:415)
at org.testng.SuiteRunner.run(SuiteRunner.java:364)
at org.testng.SuiteRunnerWorker.runSuite(SuiteRunnerWorker.java:52)
at org.testng.SuiteRunnerWorker.run(SuiteRunnerWorker.java:84)
at org.testng.TestNG.runSuitesSequentially(TestNG.java:1208)
at org.testng.TestNG.runSuitesLocally(TestNG.java:1137)
at org.testng.TestNG.runSuites(TestNG.java:1049)
at org.testng.TestNG.run(TestNG.java:1017)
at org.testng.remote.AbstractRemoteTestNG.run(AbstractRemoteTestNG.java:114)
at org.testng.remote.RemoteTestNG.initAndRun(RemoteTestNG.java:251)
at org.testng.remote.RemoteTestNG.main(RemoteTestNG.java:77)
Caused by: org.testng.internal.thread.ThreadTimeoutException: Method practice.InvocationTestCount.test1() didn't finish within the time-out 2
]]>
    </error>
  </testcase> <!-- test1 -->
  <testcase name="test1" time="0.006" classname="practice.InvocationTestCount"/>
  <testcase name="test1" time="0.007" classname="practice.InvocationTestCount"/>
</testsuite> <!-- practice.InvocationTestCount -->
